{
  "artifacts": [], 
  "command": "main", 
  "experiment": {
    "base_dir": "/home/v-chaoqw/MYSFC-ORI", 
    "dependencies": [
      "numpy==1.12.1", 
      "sacred==0.7.2"
    ], 
    "mainfile": "configuration.py", 
    "name": "Siam-FC", 
    "repositories": [], 
    "sources": [
      [
        "configuration.py", 
        "_sources/configuration_bec8189afb7d26af3b3a0b0d61ded62c.py"
      ]
    ]
  }, 
  "fail_trace": [
    "Traceback (most recent call last):\n", 
    "  File \"/home/v-chaoqw/anaconda2/envs/hdrnet/lib/python2.7/site-packages/sacred/config/captured_function.py\", line 48, in captured_function\n    result = wrapped(*args, **kwargs)\n", 
    "  File \"train_track_model.py\", line 285, in main\n    saver0.restore(sess, tf.train.latest_checkpoint(\"/home/v-chaoqw/MYSFC-ORI/track_model_checkpoints/SFC-only/\"))\n", 
    "  File \"/home/v-chaoqw/anaconda2/envs/hdrnet/lib/python2.7/site-packages/tensorflow/python/training/saver.py\", line 1457, in restore\n    {self.saver_def.filename_tensor_name: save_path})\n", 
    "  File \"/home/v-chaoqw/anaconda2/envs/hdrnet/lib/python2.7/site-packages/tensorflow/python/client/session.py\", line 778, in run\n    run_metadata_ptr)\n", 
    "  File \"/home/v-chaoqw/anaconda2/envs/hdrnet/lib/python2.7/site-packages/tensorflow/python/client/session.py\", line 982, in _run\n    feed_dict_string, options, run_metadata)\n", 
    "  File \"/home/v-chaoqw/anaconda2/envs/hdrnet/lib/python2.7/site-packages/tensorflow/python/client/session.py\", line 1032, in _do_run\n    target_list, options, run_metadata)\n", 
    "  File \"/home/v-chaoqw/anaconda2/envs/hdrnet/lib/python2.7/site-packages/tensorflow/python/client/session.py\", line 1052, in _do_call\n    raise type(e)(node_def, op, message)\n", 
    "NotFoundError: Key OptimizeLoss/siamese_fc/conv4/b1/BatchNorm/gamma/Adam_1 not found in checkpoint\n\t [[Node: save_1/RestoreV2_27 = RestoreV2[dtypes=[DT_FLOAT], _device=\"/job:localhost/replica:0/task:0/cpu:0\"](_recv_save_1/Const_0, save_1/RestoreV2_27/tensor_names, save_1/RestoreV2_27/shape_and_slices)]]\n\t [[Node: save_1/RestoreV2_59/_87 = _Recv[client_terminated=false, recv_device=\"/job:localhost/replica:0/task:0/gpu:0\", send_device=\"/job:localhost/replica:0/task:0/cpu:0\", send_device_incarnation=1, tensor_name=\"edge_484_save_1/RestoreV2_59\", tensor_type=DT_FLOAT, _device=\"/job:localhost/replica:0/task:0/gpu:0\"]()]]\n\nCaused by op u'save_1/RestoreV2_27', defined at:\n  File \"train_track_model.py\", line 370, in <module>\n    ex.run_commandline()\n  File \"/home/v-chaoqw/anaconda2/envs/hdrnet/lib/python2.7/site-packages/sacred/experiment.py\", line 250, in run_commandline\n    return self.run(cmd_name, config_updates, named_configs, {}, args)\n  File \"/home/v-chaoqw/anaconda2/envs/hdrnet/lib/python2.7/site-packages/sacred/experiment.py\", line 199, in run\n    run()\n  File \"/home/v-chaoqw/anaconda2/envs/hdrnet/lib/python2.7/site-packages/sacred/run.py\", line 229, in __call__\n    self.result = self.main_function(*args)\n  File \"/home/v-chaoqw/anaconda2/envs/hdrnet/lib/python2.7/site-packages/sacred/config/captured_function.py\", line 48, in captured_function\n    result = wrapped(*args, **kwargs)\n  File \"train_track_model.py\", line 278, in main\n    saver0 = tf.train.Saver(var_0)\n  File \"/home/v-chaoqw/anaconda2/envs/hdrnet/lib/python2.7/site-packages/tensorflow/python/training/saver.py\", line 1056, in __init__\n    self.build()\n  File \"/home/v-chaoqw/anaconda2/envs/hdrnet/lib/python2.7/site-packages/tensorflow/python/training/saver.py\", line 1086, in build\n    restore_sequentially=self._restore_sequentially)\n  File \"/home/v-chaoqw/anaconda2/envs/hdrnet/lib/python2.7/site-packages/tensorflow/python/training/saver.py\", line 691, in build\n    restore_sequentially, reshape)\n  File \"/home/v-chaoqw/anaconda2/envs/hdrnet/lib/python2.7/site-packages/tensorflow/python/training/saver.py\", line 407, in _AddRestoreOps\n    tensors = self.restore_op(filename_tensor, saveable, preferred_shard)\n  File \"/home/v-chaoqw/anaconda2/envs/hdrnet/lib/python2.7/site-packages/tensorflow/python/training/saver.py\", line 247, in restore_op\n    [spec.tensor.dtype])[0])\n  File \"/home/v-chaoqw/anaconda2/envs/hdrnet/lib/python2.7/site-packages/tensorflow/python/ops/gen_io_ops.py\", line 669, in restore_v2\n    dtypes=dtypes, name=name)\n  File \"/home/v-chaoqw/anaconda2/envs/hdrnet/lib/python2.7/site-packages/tensorflow/python/framework/op_def_library.py\", line 768, in apply_op\n    op_def=op_def)\n  File \"/home/v-chaoqw/anaconda2/envs/hdrnet/lib/python2.7/site-packages/tensorflow/python/framework/ops.py\", line 2336, in create_op\n    original_op=self._default_original_op, op_def=op_def)\n  File \"/home/v-chaoqw/anaconda2/envs/hdrnet/lib/python2.7/site-packages/tensorflow/python/framework/ops.py\", line 1228, in __init__\n    self._traceback = _extract_stack()\n\nNotFoundError (see above for traceback): Key OptimizeLoss/siamese_fc/conv4/b1/BatchNorm/gamma/Adam_1 not found in checkpoint\n\t [[Node: save_1/RestoreV2_27 = RestoreV2[dtypes=[DT_FLOAT], _device=\"/job:localhost/replica:0/task:0/cpu:0\"](_recv_save_1/Const_0, save_1/RestoreV2_27/tensor_names, save_1/RestoreV2_27/shape_and_slices)]]\n\t [[Node: save_1/RestoreV2_59/_87 = _Recv[client_terminated=false, recv_device=\"/job:localhost/replica:0/task:0/gpu:0\", send_device=\"/job:localhost/replica:0/task:0/cpu:0\", send_device_incarnation=1, tensor_name=\"edge_484_save_1/RestoreV2_59\", tensor_type=DT_FLOAT, _device=\"/job:localhost/replica:0/task:0/gpu:0\"]()]]\n\n"
  ], 
  "heartbeat": "2017-12-14T10:38:15.390088", 
  "host": {
    "ENV": {}, 
    "cpu": "Intel(R) Xeon(R) CPU E5-2690 v3 @ 2.60GHz", 
    "gpus": {
      "driver_version": "384.81", 
      "gpus": [
        {
          "model": "Tesla K80", 
          "persistence_mode": false, 
          "total_memory": 11439
        }, 
        {
          "model": "Tesla K80", 
          "persistence_mode": false, 
          "total_memory": 11439
        }
      ]
    }, 
    "hostname": "GCRAZGDL116", 
    "os": [
      "Linux", 
      "Linux-4.4.0-101-generic-x86_64-with-debian-stretch-sid"
    ], 
    "python_version": "2.7.14"
  }, 
  "meta": {
    "command": "main", 
    "options": {
      "--beat_interval": null, 
      "--capture": null, 
      "--comment": null, 
      "--debug": false, 
      "--enforce_clean": false, 
      "--file_storage": null, 
      "--force": false, 
      "--help": false, 
      "--loglevel": null, 
      "--mongo_db": null, 
      "--name": null, 
      "--pdb": false, 
      "--print_config": false, 
      "--priority": null, 
      "--queue": false, 
      "--sql": null, 
      "--tiny_db": null, 
      "--unobserved": false, 
      "COMMAND": null, 
      "UPDATE": [
        "sfc", 
        "workstation"
      ], 
      "help": false, 
      "with": true
    }
  }, 
  "resources": [], 
  "result": null, 
  "start_time": "2017-12-14T10:37:44.712334", 
  "status": "FAILED", 
  "stop_time": "2017-12-14T10:38:15.391988"
}