{
  "artifacts": [], 
  "command": "main", 
  "experiment": {
    "base_dir": "/home/v-chaoqw/MYSFC-ORI", 
    "dependencies": [
      "numpy==1.13.3", 
      "sacred==0.7.2"
    ], 
    "mainfile": "configuration.py", 
    "name": "Siam-FC", 
    "repositories": [], 
    "sources": [
      [
        "configuration.py", 
        "_sources/configuration_e3604cb3d08ac26eb84e21477085cd65.py"
      ]
    ]
  }, 
  "fail_trace": [
    "Traceback (most recent call last):\n", 
    "  File \"/home/v-chaoqw/anaconda2/envs/hdrnet/lib/python2.7/site-packages/sacred/config/captured_function.py\", line 48, in captured_function\n    result = wrapped(*args, **kwargs)\n", 
    "  File \"train_track_model.py\", line 246, in main\n    _, loss, batch_loss = sess.run([train_op, model.total_loss, model.batch_loss])\n", 
    "  File \"/home/v-chaoqw/anaconda2/envs/hdrnet/lib/python2.7/site-packages/tensorflow/python/client/session.py\", line 778, in run\n    run_metadata_ptr)\n", 
    "  File \"/home/v-chaoqw/anaconda2/envs/hdrnet/lib/python2.7/site-packages/tensorflow/python/client/session.py\", line 982, in _run\n    feed_dict_string, options, run_metadata)\n", 
    "  File \"/home/v-chaoqw/anaconda2/envs/hdrnet/lib/python2.7/site-packages/tensorflow/python/client/session.py\", line 1032, in _do_run\n    target_list, options, run_metadata)\n", 
    "  File \"/home/v-chaoqw/anaconda2/envs/hdrnet/lib/python2.7/site-packages/tensorflow/python/client/session.py\", line 1052, in _do_call\n    raise type(e)(node_def, op, message)\n", 
    "InvalidArgumentError: Input to reshape is a tensor with 991232 values, but the requested shape requires a multiple of 3072\n\t [[Node: siamese_fc_1/conv5/def/conv21_offset_1/Reshape_2 = Reshape[T=DT_FLOAT, Tshape=DT_INT32, _device=\"/job:localhost/replica:0/task:0/gpu:0\"](siamese_fc_1/conv5/def/conv21_offset_1/Reshape, siamese_fc_1/conv5/def/conv21_offset_1/Reshape_2/shape)]]\n\t [[Node: Compute_loss/batch_loss/_189 = _Recv[client_terminated=false, recv_device=\"/job:localhost/replica:0/task:0/cpu:0\", send_device=\"/job:localhost/replica:0/task:0/gpu:0\", send_device_incarnation=1, tensor_name=\"edge_6855_Compute_loss/batch_loss\", tensor_type=DT_FLOAT, _device=\"/job:localhost/replica:0/task:0/cpu:0\"]()]]\n\nCaused by op u'siamese_fc_1/conv5/def/conv21_offset_1/Reshape_2', defined at:\n  File \"train_track_model.py\", line 274, in <module>\n    ex.run_commandline()\n  File \"/home/v-chaoqw/anaconda2/envs/hdrnet/lib/python2.7/site-packages/sacred/experiment.py\", line 250, in run_commandline\n    return self.run(cmd_name, config_updates, named_configs, {}, args)\n  File \"/home/v-chaoqw/anaconda2/envs/hdrnet/lib/python2.7/site-packages/sacred/experiment.py\", line 199, in run\n    run()\n  File \"/home/v-chaoqw/anaconda2/envs/hdrnet/lib/python2.7/site-packages/sacred/run.py\", line 229, in __call__\n    self.result = self.main_function(*args)\n  File \"/home/v-chaoqw/anaconda2/envs/hdrnet/lib/python2.7/site-packages/sacred/config/captured_function.py\", line 48, in captured_function\n    result = wrapped(*args, **kwargs)\n  File \"train_track_model.py\", line 125, in main\n    response=model.build()\n  File \"/home/v-chaoqw/MYSFC-ORI/models/track_model.py\", line 269, in build\n    self.build_image_embeddings()\n  File \"/home/v-chaoqw/MYSFC-ORI/models/track_model.py\", line 137, in build_image_embeddings\n    self.instance_embeds, _ = embedding_fn(self.instances, reuse=True)\n  File \"/home/v-chaoqw/MYSFC-ORI/embeddings/embedding_factory.py\", line 70, in network_fn\n    return func(images, reuse=reuse)\n  File \"/home/v-chaoqw/MYSFC-ORI/embeddings/siamese_fc.py\", line 252, in siamese_fc\n    l2_offset = ConvOffset2D(128, name='conv21_offset')(b2)\n  File \"/home/v-chaoqw/anaconda2/envs/hdrnet/lib/python2.7/site-packages/keras/engine/topology.py\", line 602, in __call__\n    output = self.call(inputs, **kwargs)\n  File \"/home/v-chaoqw/MYSFC-ORI/embeddings/deform2.py\", line 52, in call\n    x_offset = tf_batch_map_offsets(x, offsets)\n  File \"/home/v-chaoqw/MYSFC-ORI/embeddings/deform1.py\", line 156, in tf_batch_map_offsets\n    offsets = tf.reshape(offsets, (batch_size, -1, 2))\n  File \"/home/v-chaoqw/anaconda2/envs/hdrnet/lib/python2.7/site-packages/tensorflow/python/ops/gen_array_ops.py\", line 2510, in reshape\n    name=name)\n  File \"/home/v-chaoqw/anaconda2/envs/hdrnet/lib/python2.7/site-packages/tensorflow/python/framework/op_def_library.py\", line 768, in apply_op\n    op_def=op_def)\n  File \"/home/v-chaoqw/anaconda2/envs/hdrnet/lib/python2.7/site-packages/tensorflow/python/framework/ops.py\", line 2336, in create_op\n    original_op=self._default_original_op, op_def=op_def)\n  File \"/home/v-chaoqw/anaconda2/envs/hdrnet/lib/python2.7/site-packages/tensorflow/python/framework/ops.py\", line 1228, in __init__\n    self._traceback = _extract_stack()\n\nInvalidArgumentError (see above for traceback): Input to reshape is a tensor with 991232 values, but the requested shape requires a multiple of 3072\n\t [[Node: siamese_fc_1/conv5/def/conv21_offset_1/Reshape_2 = Reshape[T=DT_FLOAT, Tshape=DT_INT32, _device=\"/job:localhost/replica:0/task:0/gpu:0\"](siamese_fc_1/conv5/def/conv21_offset_1/Reshape, siamese_fc_1/conv5/def/conv21_offset_1/Reshape_2/shape)]]\n\t [[Node: Compute_loss/batch_loss/_189 = _Recv[client_terminated=false, recv_device=\"/job:localhost/replica:0/task:0/cpu:0\", send_device=\"/job:localhost/replica:0/task:0/gpu:0\", send_device_incarnation=1, tensor_name=\"edge_6855_Compute_loss/batch_loss\", tensor_type=DT_FLOAT, _device=\"/job:localhost/replica:0/task:0/cpu:0\"]()]]\n\n"
  ], 
  "heartbeat": "2017-12-06T08:26:16.799094", 
  "host": {
    "ENV": {}, 
    "cpu": "Intel(R) Xeon(R) CPU E5-2690 v3 @ 2.60GHz", 
    "gpus": {
      "driver_version": "375.66", 
      "gpus": [
        {
          "model": "Tesla K80", 
          "persistence_mode": false, 
          "total_memory": 11439
        }, 
        {
          "model": "Tesla K80", 
          "persistence_mode": false, 
          "total_memory": 11439
        }
      ]
    }, 
    "hostname": "GCRAZGDL116", 
    "os": [
      "Linux", 
      "Linux-4.4.0-78-generic-x86_64-with-debian-stretch-sid"
    ], 
    "python_version": "2.7.14"
  }, 
  "meta": {
    "command": "main", 
    "options": {
      "--beat_interval": null, 
      "--capture": null, 
      "--comment": null, 
      "--debug": false, 
      "--enforce_clean": false, 
      "--file_storage": null, 
      "--force": false, 
      "--help": false, 
      "--loglevel": null, 
      "--mongo_db": null, 
      "--name": null, 
      "--pdb": false, 
      "--print_config": false, 
      "--priority": null, 
      "--queue": false, 
      "--sql": null, 
      "--tiny_db": null, 
      "--unobserved": false, 
      "COMMAND": null, 
      "UPDATE": [
        "sfc", 
        "workstation"
      ], 
      "help": false, 
      "with": true
    }
  }, 
  "resources": [], 
  "result": null, 
  "start_time": "2017-12-06T08:25:51.528045", 
  "status": "FAILED", 
  "stop_time": "2017-12-06T08:26:16.801838"
}