{
  "artifacts": [], 
  "command": "main", 
  "experiment": {
    "base_dir": "/home/v-chaoqw/MYSFC-ORI", 
    "dependencies": [
      "numpy==1.12.1", 
      "sacred==0.7.2"
    ], 
    "mainfile": "configuration.py", 
    "name": "Siam-FC", 
    "repositories": [], 
    "sources": [
      [
        "configuration.py", 
        "_sources/configuration_03c4dcf5f0716a8c1f3dbd776b394412.py"
      ]
    ]
  }, 
  "fail_trace": [
    "Traceback (most recent call last):\n", 
    "  File \"/home/v-chaoqw/anaconda2/envs/hdrnet/lib/python2.7/site-packages/sacred/config/captured_function.py\", line 48, in captured_function\n    result = wrapped(*args, **kwargs)\n", 
    "  File \"train_track_model.py\", line 218, in main\n    saver0.restore(sess, tf.train.latest_checkpoint(\"/home/v-chaoqw/MYSFC-ORI/track_model_checkpoints/SFC-1/\"))\n", 
    "  File \"/home/v-chaoqw/anaconda2/envs/hdrnet/lib/python2.7/site-packages/tensorflow/python/training/saver.py\", line 1439, in restore\n    {self.saver_def.filename_tensor_name: save_path})\n", 
    "  File \"/home/v-chaoqw/anaconda2/envs/hdrnet/lib/python2.7/site-packages/tensorflow/python/client/session.py\", line 767, in run\n    run_metadata_ptr)\n", 
    "  File \"/home/v-chaoqw/anaconda2/envs/hdrnet/lib/python2.7/site-packages/tensorflow/python/client/session.py\", line 965, in _run\n    feed_dict_string, options, run_metadata)\n", 
    "  File \"/home/v-chaoqw/anaconda2/envs/hdrnet/lib/python2.7/site-packages/tensorflow/python/client/session.py\", line 1015, in _do_run\n    target_list, options, run_metadata)\n", 
    "  File \"/home/v-chaoqw/anaconda2/envs/hdrnet/lib/python2.7/site-packages/tensorflow/python/client/session.py\", line 1035, in _do_call\n    raise type(e)(node_def, op, message)\n", 
    "NotFoundError: Key siamese_fc/conv5/b1/biases not found in checkpoint\n\t [[Node: save_1/RestoreV2_32 = RestoreV2[dtypes=[DT_FLOAT], _device=\"/job:localhost/replica:0/task:0/cpu:0\"](_recv_save_1/Const_0, save_1/RestoreV2_32/tensor_names, save_1/RestoreV2_32/shape_and_slices)]]\n\nCaused by op u'save_1/RestoreV2_32', defined at:\n  File \"train_track_model.py\", line 282, in <module>\n    ex.run_commandline()\n  File \"/home/v-chaoqw/anaconda2/envs/hdrnet/lib/python2.7/site-packages/sacred/experiment.py\", line 250, in run_commandline\n    return self.run(cmd_name, config_updates, named_configs, {}, args)\n  File \"/home/v-chaoqw/anaconda2/envs/hdrnet/lib/python2.7/site-packages/sacred/experiment.py\", line 199, in run\n    run()\n  File \"/home/v-chaoqw/anaconda2/envs/hdrnet/lib/python2.7/site-packages/sacred/run.py\", line 229, in __call__\n    self.result = self.main_function(*args)\n  File \"/home/v-chaoqw/anaconda2/envs/hdrnet/lib/python2.7/site-packages/sacred/config/captured_function.py\", line 48, in captured_function\n    result = wrapped(*args, **kwargs)\n  File \"train_track_model.py\", line 212, in main\n    saver0 = tf.train.Saver(var_0)\n  File \"/home/v-chaoqw/anaconda2/envs/hdrnet/lib/python2.7/site-packages/tensorflow/python/training/saver.py\", line 1051, in __init__\n    self.build()\n  File \"/home/v-chaoqw/anaconda2/envs/hdrnet/lib/python2.7/site-packages/tensorflow/python/training/saver.py\", line 1081, in build\n    restore_sequentially=self._restore_sequentially)\n  File \"/home/v-chaoqw/anaconda2/envs/hdrnet/lib/python2.7/site-packages/tensorflow/python/training/saver.py\", line 675, in build\n    restore_sequentially, reshape)\n  File \"/home/v-chaoqw/anaconda2/envs/hdrnet/lib/python2.7/site-packages/tensorflow/python/training/saver.py\", line 402, in _AddRestoreOps\n    tensors = self.restore_op(filename_tensor, saveable, preferred_shard)\n  File \"/home/v-chaoqw/anaconda2/envs/hdrnet/lib/python2.7/site-packages/tensorflow/python/training/saver.py\", line 242, in restore_op\n    [spec.tensor.dtype])[0])\n  File \"/home/v-chaoqw/anaconda2/envs/hdrnet/lib/python2.7/site-packages/tensorflow/python/ops/gen_io_ops.py\", line 668, in restore_v2\n    dtypes=dtypes, name=name)\n  File \"/home/v-chaoqw/anaconda2/envs/hdrnet/lib/python2.7/site-packages/tensorflow/python/framework/op_def_library.py\", line 763, in apply_op\n    op_def=op_def)\n  File \"/home/v-chaoqw/anaconda2/envs/hdrnet/lib/python2.7/site-packages/tensorflow/python/framework/ops.py\", line 2395, in create_op\n    original_op=self._default_original_op, op_def=op_def)\n  File \"/home/v-chaoqw/anaconda2/envs/hdrnet/lib/python2.7/site-packages/tensorflow/python/framework/ops.py\", line 1264, in __init__\n    self._traceback = _extract_stack()\n\nNotFoundError (see above for traceback): Key siamese_fc/conv5/b1/biases not found in checkpoint\n\t [[Node: save_1/RestoreV2_32 = RestoreV2[dtypes=[DT_FLOAT], _device=\"/job:localhost/replica:0/task:0/cpu:0\"](_recv_save_1/Const_0, save_1/RestoreV2_32/tensor_names, save_1/RestoreV2_32/shape_and_slices)]]\n\n"
  ], 
  "heartbeat": "2017-12-06T12:28:41.782110", 
  "host": {
    "ENV": {}, 
    "cpu": "Intel(R) Xeon(R) CPU E5-2690 v3 @ 2.60GHz", 
    "hostname": "GCRAZGDL116", 
    "os": [
      "Linux", 
      "Linux-4.4.0-101-generic-x86_64-with-debian-stretch-sid"
    ], 
    "python_version": "2.7.14"
  }, 
  "meta": {
    "command": "main", 
    "options": {
      "--beat_interval": null, 
      "--capture": null, 
      "--comment": null, 
      "--debug": false, 
      "--enforce_clean": false, 
      "--file_storage": null, 
      "--force": false, 
      "--help": false, 
      "--loglevel": null, 
      "--mongo_db": null, 
      "--name": null, 
      "--pdb": false, 
      "--print_config": false, 
      "--priority": null, 
      "--queue": false, 
      "--sql": null, 
      "--tiny_db": null, 
      "--unobserved": false, 
      "COMMAND": null, 
      "UPDATE": [
        "sfc", 
        "workstation"
      ], 
      "help": false, 
      "with": true
    }
  }, 
  "resources": [], 
  "result": null, 
  "start_time": "2017-12-06T12:28:30.734658", 
  "status": "FAILED", 
  "stop_time": "2017-12-06T12:28:41.783113"
}